<?xml version="1.0" ?>
<robot name="tourdf">

<material name="silver">
  <color rgba="0.700 0.700 0.700 1.000"/>
</material>

<!-- 移除 fixed_base 关节 -->
<!-- <joint name="fixed_base" type="fixed">
  <parent link="world"/>
  <child link="base_link"/>
  <origin xyz="0 0 0" rpy="0 0 0"/>
</joint> -->

<link name="base_link">
  <inertial>
    <origin xyz="6.912026120657246e-05 0.0005720490415996128 0.029075184860186634" rpy="0 0 0"/>
    <mass value="1.2"/>
    <inertia ixx="0.002125" iyy="0.002125" izz="0.0015" ixy="0" iyz="0" ixz="0"/>
  </inertial>
  <visual>
    <origin xyz="0 0 0" rpy="0 0 0"/>
    <geometry>
      <mesh filename="meshes/base_link.stl" scale="0.001 0.001 0.001"/>
    </geometry>
    <material name="silver"/>
    <material/>
  </visual>
  <collision>
    <origin xyz="0 0 0" rpy="0 0 0"/>
    <geometry>
      <mesh filename="meshes/base_link.stl" scale="0.001 0.001 0.001"/>
    </geometry>
  </collision>
</link>

<link name="link21">
  <inertial>
    <origin xyz="0.009331956179756715 -2.9985901183365485e-07 0.02399962139808455" rpy="0 0 0"/>
    <mass value="0.585"/>
    <inertia ixx="0.000703" iyy="0.000703" izz="0.000263" ixy="0" iyz="0" ixz="0"/>
  </inertial>
  <visual>
    <origin xyz="3.8e-05 -3.8e-05 -0.06515" rpy="0 0 0"/>
    <geometry>
      <mesh filename="meshes/link21.stl" scale="0.001 0.001 0.001"/>
    </geometry>
    <material name="silver"/>
    <material/>
  </visual>
  <collision>
    <origin xyz="3.8e-05 -3.8e-05 -0.06515" rpy="0 0 0"/>
    <geometry>
      <mesh filename="meshes/link21.stl" scale="0.001 0.001 0.001"/>
    </geometry>
  </collision>
</link>

<link name="link31">
  <inertial>
    <origin xyz="0.018958552727281412 -0.0002894631712261024 0.07973545129791977" rpy="0 0 0"/>
    <mass value="0.5"/>
    <inertia ixx="0.001333" iyy="0.001333" izz="0.0004" ixy="0" iyz="0" ixz="0"/>
  </inertial>
  <visual>
    <origin xyz="-0.049962 -3.8e-05 -0.10015" rpy="0 0 0"/>
    <geometry>
      <mesh filename="meshes/link31.stl" scale="0.001 0.001 0.001"/>
    </geometry>
    <material name="silver"/>
    <material/>
  </visual>
  <collision>
    <origin xyz="-0.049962 -3.8e-05 -0.10015" rpy="0 0 0"/>
    <geometry>
      <mesh filename="meshes/link31.stl" scale="0.001 0.001 0.001"/>
    </geometry>
  </collision>
</link>

<link name="link41">
  <inertial>
    <origin xyz="-0.019545283743454267 3.886237290085838e-07 0.06420591996606956" rpy="0 0 0"/>
    <mass value="0.05"/>
    <inertia ixx="0.000021" iyy="0.000021" izz="0.0000025" ixy="0" iyz="0" ixz="0"/>
  </inertial>
  <visual>
    <origin xyz="-0.052962 -3.8e-05 -0.28015" rpy="0 0 0"/>
    <geometry>
      <mesh filename="meshes/link41.stl" scale="0.001 0.001 0.001"/>
    </geometry>
    <material name="silver"/>
    <material/>
  </visual>
  <collision>
    <origin xyz="-0.052962 -3.8e-05 -0.28015" rpy="0 0 0"/>
    <geometry>
      <mesh filename="meshes/link41.stl" scale="0.001 0.001 0.001"/>
    </geometry>
  </collision>
</link>

<joint name="route_1" type="continuous">
  <origin xyz="-3.8e-05 3.8e-05 0.06515" rpy="0 0 0"/>
  <parent link="base_link"/>
  <child link="link21"/>
  <axis xyz="-0.0 -0.0 1.0"/>
</joint>
<transmission name="route_1_tran">
  <type>transmission_interface/SimpleTransmission</type>
  <joint name="route_1">
    <hardwareInterface>PositionJointInterface</hardwareInterface>
  </joint>
  <actuator name="route_1_actr">
    <hardwareInterface>PositionJointInterface</hardwareInterface>
    <mechanicalReduction>1</mechanicalReduction>
  </actuator>
</transmission>

<joint name="route_2" type="continuous">
  <origin xyz="0.05 0.0 0.035" rpy="0 0 0"/>
  <parent link="link21"/>
  <child link="link31"/>
  <axis xyz="-1.0 -0.0 -0.0"/>
</joint>
<transmission name="route_2_tran">
  <type>transmission_interface/SimpleTransmission</type>
  <joint name="route_2">
    <hardwareInterface>PositionJointInterface</hardwareInterface>
  </joint>
  <actuator name="route_2_actr">
    <hardwareInterface>PositionJointInterface</hardwareInterface>
    <mechanicalReduction>1</mechanicalReduction>
  </actuator>
</transmission>

<joint name="route_3" type="continuous">
  <origin xyz="0.003 0.0 0.18" rpy="0 0 0"/>
  <parent link="link31"/>
  <child link="link41"/>
  <axis xyz="1.0 -0.0 0.0"/>
</joint>
<transmission name="route_3_tran">
  <type>transmission_interface/SimpleTransmission</type>
  <joint name="route_3">
    <hardwareInterface>PositionJointInterface</hardwareInterface>
  </joint>
  <actuator name="route_3_actr">
    <hardwareInterface>PositionJointInterface</hardwareInterface>
    <mechanicalReduction>1</mechanicalReduction>
  </actuator>
</transmission>

</robot>
